Traceback (most recent call last):
  File "/Users/jellesombekke/miniconda3/envs/jupyterbook/lib/python3.9/site-packages/jupyter_cache/executors/utils.py", line 58, in single_nb_execution
    executenb(
  File "/Users/jellesombekke/miniconda3/envs/jupyterbook/lib/python3.9/site-packages/nbclient/client.py", line 1305, in execute
    return NotebookClient(nb=nb, resources=resources, km=km, **kwargs).execute()
  File "/Users/jellesombekke/miniconda3/envs/jupyterbook/lib/python3.9/site-packages/jupyter_core/utils/__init__.py", line 166, in wrapped
    return loop.run_until_complete(inner)
  File "/Users/jellesombekke/miniconda3/envs/jupyterbook/lib/python3.9/asyncio/base_events.py", line 647, in run_until_complete
    return future.result()
  File "/Users/jellesombekke/miniconda3/envs/jupyterbook/lib/python3.9/site-packages/nbclient/client.py", line 705, in async_execute
    await self.async_execute_cell(
  File "/Users/jellesombekke/miniconda3/envs/jupyterbook/lib/python3.9/site-packages/nbclient/client.py", line 1058, in async_execute_cell
    await self._check_raise_for_error(cell, cell_index, exec_reply)
  File "/Users/jellesombekke/miniconda3/envs/jupyterbook/lib/python3.9/site-packages/nbclient/client.py", line 914, in _check_raise_for_error
    raise CellExecutionError.from_cell_and_msg(cell, exec_reply_content)
nbclient.exceptions.CellExecutionError: An error occurred while executing the following cell:
------------------
import plotly.graph_objs as go
import plotly.express as px
import pandas as pd
import geopandas as gpd
import matplotlib.pyplot as plt

# Read the data from table1.csv
df = pd.read_csv('population_eu.csv')
df2 = df[df.Year.between(2000, 2017)]

df3 = pd.read_csv('aanslagen_per_jaar.csv')

colors = ['rgb(238, 75, 43)', 'rgb(252,245,245)', 'rgb(129, 133, 137)']
fig = go.Figure()

fig.add_trace(go.Bar(
    x=df2['Year'],
    y=df2["Refugees under UNHCR's mandate"],
    marker_color='rgb(238, 75, 43)',
    name="Refugees",
    yaxis='y'  
))

fig.update_layout(
    title='Aantal vluchtelingen in Europa',
    xaxis=dict(type='category'),
    yaxis=dict(range=[0, 22000000], title="Vluchtelingen onder UNHCR's mandate" , side='left'),
    xaxis_title='Jaar',
    height=500,
    bargap=0.1,
    plot_bgcolor='rgb(252,245,245)',
)

fig.show()
------------------


[0;31m---------------------------------------------------------------------------[0m
[0;31mModuleNotFoundError[0m                       Traceback (most recent call last)
Cell [0;32mIn[2], line 4[0m
[1;32m      2[0m [38;5;28;01mimport[39;00m [38;5;21;01mplotly[39;00m[38;5;21;01m.[39;00m[38;5;21;01mexpress[39;00m [38;5;28;01mas[39;00m [38;5;21;01mpx[39;00m
[1;32m      3[0m [38;5;28;01mimport[39;00m [38;5;21;01mpandas[39;00m [38;5;28;01mas[39;00m [38;5;21;01mpd[39;00m
[0;32m----> 4[0m [38;5;28;01mimport[39;00m [38;5;21;01mgeopandas[39;00m [38;5;28;01mas[39;00m [38;5;21;01mgpd[39;00m
[1;32m      5[0m [38;5;28;01mimport[39;00m [38;5;21;01mmatplotlib[39;00m[38;5;21;01m.[39;00m[38;5;21;01mpyplot[39;00m [38;5;28;01mas[39;00m [38;5;21;01mplt[39;00m
[1;32m      7[0m [38;5;66;03m# Read the data from table1.csv[39;00m

[0;31mModuleNotFoundError[0m: No module named 'geopandas'

